<?xml version="1.0" encoding="utf-8"?>
<!-- This URDF was automatically created by SolidWorks to URDF Exporter! Originally created by Stephen Brawner (brawner@gmail.com) 
     Commit Version: 1.6.0-1-g15f4949  Build Version: 1.6.7594.29634
     For more information, please see http://wiki.ros.org/sw_urdf_exporter -->
<robot
  name="horizonforce">
  <link
    name="base_link">
    <inertial>
      <origin
        xyz="0.33941 -0.54032 0.36444"
        rpy="0 0 0" />
      <mass
        value="247.35" />
      <inertia
        ixx="16.792"
        ixy="-1.2534E-17"
        ixz="-1.1221E-15"
        iyy="16.917"
        iyz="1.8332E-14"
        izz="15.209" />
    </inertial>
    <visual>
      <origin
        xyz="0 0 0"
        rpy="0 0 0" />
      <geometry>
        <mesh
          filename="package://horizonforce/meshes/base_link.STL" />
      </geometry>
      <material
        name="">
        <color
          rgba="0.79216 0.81961 0.93333 1" />
      </material>
    </visual>
    <collision>
      <origin
        xyz="0 0 0"
        rpy="0 0 0" />
      <geometry>
        <mesh
          filename="package://horizonforce/meshes/base_link.STL" />
      </geometry>
    </collision>
  </link>
  <link
    name="link1">
    <inertial>
      <origin
        xyz="0.014973 0.33223 -2.8596E-09"
        rpy="0 0 0" />
      <mass
        value="0.43373" />
      <inertia
        ixx="0.0023488"
        ixy="1.3875E-06"
        ixz="9.3909E-10"
        iyy="0.00018319"
        iyz="-8.8506E-11"
        izz="0.0023838" />
    </inertial>
    <visual>
      <origin
        xyz="0 0 0"
        rpy="0 0 0" />
      <geometry>
        <mesh
          filename="package://horizonforce/meshes/link1.STL" />
      </geometry>
      <material
        name="">
        <color
          rgba="0.79216 0.81961 0.93333 1" />
      </material>
    </visual>
    <collision>
      <origin
        xyz="0 0 0"
        rpy="0 0 0" />
      <geometry>
        <mesh
          filename="package://horizonforce/meshes/link1.STL" />
      </geometry>
    </collision>
  </link>
  <joint
    name="joint1"
    type="fixed">
    <origin
      xyz="0.53033 -0.59566 0.73931"
      rpy="-3.1416 0 -0.0046535" />
    <parent
      link="base_link" />
    <child
      link="link1" />
    <axis
      xyz="0 0 0" />
  </joint>
  <link
    name="link2">
    <inertial>
      <origin
        xyz="-0.00022622 0.075187 -0.0125"
        rpy="0 0 0" />
      <mass
        value="0.32435" />
      <inertia
        ixx="0.00037151"
        ixy="-2.8054E-06"
        ixz="-5.1364E-10"
        iyy="0.00015095"
        iyz="8.2392E-10"
        izz="0.00040236" />
    </inertial>
    <visual>
      <origin
        xyz="0 0 0"
        rpy="0 0 0" />
      <geometry>
        <mesh
          filename="package://horizonforce/meshes/link2.STL" />
      </geometry>
      <material
        name="">
        <color
          rgba="0.96078 0.96078 0.94902 1" />
      </material>
    </visual>
    <collision>
      <origin
        xyz="0 0 0"
        rpy="0 0 0" />
      <geometry>
        <mesh
          filename="package://horizonforce/meshes/link2.STL" />
      </geometry>
    </collision>
  </link>
  <joint
    name="joint2"
    type="revolute">
    <origin
      xyz="0 0.45 0"
      rpy="-1.5708 -1.5527 1.5708" />
    <parent
      link="link1" />
    <child
      link="link2" />
    <axis
      xyz="0 0 1" />
    <limit
      lower="-0.7854"
      upper="0.7854"
      effort="0"
      velocity="0" />
  </joint>
  <link
    name="link3">
    <inertial>
      <origin
        xyz="-0.034259 3.8013E-05 0.0024758"
        rpy="0 0 0" />
      <mass
        value="0.12179" />
      <inertia
        ixx="6.3147E-05"
        ixy="-1.6046E-06"
        ixz="-1.2006E-07"
        iyy="0.00013445"
        iyz="-1.4847E-09"
        izz="9.6578E-05" />
    </inertial>
    <visual>
      <origin
        xyz="0 0 0"
        rpy="0 0 0" />
      <geometry>
        <mesh
          filename="package://horizonforce/meshes/link3.STL" />
      </geometry>
      <material
        name="">
        <color
          rgba="0.96078 0.96078 0.94902 1" />
      </material>
    </visual>
    <collision>
      <origin
        xyz="0 0 0"
        rpy="0 0 0" />
      <geometry>
        <mesh
          filename="package://horizonforce/meshes/link3.STL" />
      </geometry>
    </collision>
  </link>
  <joint
    name="joint3"
    type="revolute">
    <origin
      xyz="0 0.16 -0.0125"
      rpy="-1.5708 -0.0054927 -1.5708" />
    <parent
      link="link2" />
    <child
      link="link3" />
    <axis
      xyz="0 0 1" />
    <limit
      lower="-0.7854"
      upper="0.7854"
      effort="0"
      velocity="0" />
  </joint>
  <link
    name="link4">
    <inertial>
      <origin
        xyz="-0.0018508 0.043793 0.0063844"
        rpy="0 0 0" />
      <mass
        value="0.11343" />
      <inertia
        ixx="0.00015269"
        ixy="6.3432E-06"
        ixz="1.6637E-08"
        iyy="5.7464E-05"
        iyz="-4.5966E-08"
        izz="0.00010402" />
    </inertial>
    <visual>
      <origin
        xyz="0 0 0"
        rpy="0 0 0" />
      <geometry>
        <mesh
          filename="package://horizonforce/meshes/link4.STL" />
      </geometry>
      <material
        name="">
        <color
          rgba="0.79216 0.81961 0.93333 1" />
      </material>
    </visual>
    <collision>
      <origin
        xyz="0 0 0"
        rpy="0 0 0" />
      <geometry>
        <mesh
          filename="package://horizonforce/meshes/link4.STL" />
      </geometry>
    </collision>
  </link>
  <joint
    name="joint4"
    type="revolute">
    <origin
      xyz="-0.075 -0.0004747 0"
      rpy="0 -0.0013254 1.5758" />
    <parent
      link="link3" />
    <child
      link="link4" />
    <axis
      xyz="0 0 1" />
    <limit
      lower="-0.7854"
      upper="0.7854"
      effort="0"
      velocity="0" />
  </joint>
</robot>